Workbook

Sheet Instrucciones
A1: FICHAS TÉCNICAS DE INVENTARIO TIC
A2: Plantilla para registrar, controlar y dar seguimiento a los activos de Tecnologías de la Información y Comunicación
A4: QUÉ ES
A5: Ficha técnica TIC | B5: Registro individual de un activo informático (equipo, servidor, dispositivo de red, periférico o licencia) con su identificación, características técnicas, ubicación, responsable, adquisición, garantía, mantenimiento y estado. Sirve para controlar el inventario, planificar renovaciones y presupuesto, y responder auditorías.
A6: CÓMO USAR EL LIBRO
A7: Paso 1 | B7: Revise la hoja 'Listas' y adapte las áreas y demás opciones a su organización (los desplegables se actualizan solos).
A8: Paso 2 | B8: Registre cada activo UNA vez en 'Inventario General'. El código patrimonial/interno es la llave que enlaza todas las demás hojas.
A9: Paso 3 | B9: Complete la ficha especializada según el tipo de activo: 'Equipos de Cómputo', 'Servidores', 'Red y Comunicaciones' o 'Periféricos'. Elija el código en la columna A y la marca, el modelo y el responsable se traen solos.
A10: Paso 4 | B10: Registre licencias en 'Software y Licencias', intervenciones en 'Mantenimiento' y entregas/devoluciones en 'Asignaciones'.
A11: Paso 5 | B11: Para imprimir o firmar la ficha de un activo, use 'Ficha Individual': escriba o elija el código y se arma sola. 'Resumen' muestra los indicadores.
A12: LEYENDA DE COLORES
A13: Encabezado azul oscuro | B13: Columna que usted llena.
A14: Encabezado gris | B14: Columna calculada automáticamente (fórmula). No la sobrescriba.
A15: Fondo amarillo claro | B15: Fila de ejemplo con datos ficticios. Reemplácela o bórrela (solo las celdas de fondo amarillo, no las grises).
A16: Celdas grises | B16: Contienen fórmulas (antigüedad, estado de garantía, datos traídos del inventario, etc.).
A17: HOJAS DEL LIBRO
A18: Resumen | B18: Indicadores: total de activos, valor, garantías vencidas, activos a renovar, licencias por vencer, mantenimientos pendientes y desgloses por tipo, estado y área.
A19: Inventario General | B19: Registro maestro de todos los activos (hasta 300). Calcula antigüedad, estado de garantía, vida útil restante y situación de renovación.
A20: Ficha Individual | B20: Ficha imprimible de un activo: junta datos generales, técnicos, historial de mantenimiento y espacios para firmas.
A21: Equipos de Cómputo | B21: Laptops, PC, all-in-one, workstations, tablets: procesador, memoria, almacenamiento, sistema operativo, red, seguridad.
A22: Servidores | B22: Rol, procesadores, RAM, RAID, virtualización, ubicación en rack, consumo, respaldos.
A23: Red y Comunicaciones | B23: Switches, routers, firewalls, access points: puertos, PoE, firmware, IP de gestión, VLAN, proveedor de internet.
A24: Periféricos | B24: Impresoras, escáneres, monitores, proyectores, UPS, teléfonos IP, cámaras: conexión, consumibles, contador.
A25: Software y Licencias | B25: Licencias adquiridas vs. en uso, tipo, vencimiento y costo. Avisa las que están por vencer o vencidas.
A26: Mantenimiento | B26: Bitácora de mantenimientos preventivos, correctivos y actualizaciones, con costos y fecha del próximo mantenimiento.
A27: Asignaciones | B27: Historial de quién tuvo cada equipo, con fechas de entrega/devolución y número de acta.
A28: Listas | B28: Catálogos de los desplegables y parámetros de alerta. Puede agregar opciones debajo de las existentes.
A29: SUPUESTOS Y PARÁMETROS
A30: Alerta de licencias | B30: Una licencia se marca 'Por vencer' cuando faltan 60 días o menos para su vencimiento (parámetro editable en Listas, celda T2).
A31: Alerta de renovación | B31: Un activo se marca 'Próximo a renovar' cuando le queda 1 año o menos de vida útil (parámetro editable en Listas, celda T3).
A32: Antigüedad | B32: Se calcula con la fecha de hoy y la fecha de adquisición (años = días / 365.25). Los datos de ejemplo son ficticios.
A33: Moneda | B33: Los importes están en soles (S/). Cambie el formato de celda si trabaja con otra moneda.

Sheet Resumen
A1: RESUMEN DEL INVENTARIO TIC
A2: Todo se calcula automáticamente a partir de las demás hojas.
A3: Indicador | B3: Valor | D3: Activos por tipo | E3: Cantidad | F3: Valor (S/)
A4: Total de activos registrados | B4: =COUNTA('Inventario General'!$A$5:$A$304) -> 4 | D4: =IF(Listas!A2="","",Listas!A2) -> Laptop | E4: =IF(D4="","",COUNTIF('Inventario General'!$B$5:$B$304,D4)) -> 1 | F4: =IF(D4="","",SUMIF('Inventario General'!$B$5:$B$304,D4,'Inventario General'!$N$5:$N$304)) -> 3850
A5: Valor total de adquisición (S/) | B5: =SUM('Inventario General'!$N$5:$N$304) -> 40400 | D5: =IF(Listas!A3="","",Listas!A3) -> PC de escritorio | E5: =IF(D5="","",COUNTIF('Inventario General'!$B$5:$B$304,D5)) -> 0 | F5: =IF(D5="","",SUMIF('Inventario General'!$B$5:$B$304,D5,'Inventario General'!$N$5:$N$304)) -> 0
A6: Activos operativos | B6: =COUNTIF('Inventario General'!$Q$5:$Q$304,"Operativo") -> 4 | D6: =IF(Listas!A4="","",Listas!A4) -> All-in-one | E6: =IF(D6="","",COUNTIF('Inventario General'!$B$5:$B$304,D6)) -> 0 | F6: =IF(D6="","",SUMIF('Inventario General'!$B$5:$B$304,D6,'Inventario General'!$N$5:$N$304)) -> 0
A7: Activos con garantía vencida | B7: =COUNTIF('Inventario General'!$U$5:$U$304,"Vencida") -> 2 | D7: =IF(Listas!A5="","",Listas!A5) -> Workstation | E7: =IF(D7="","",COUNTIF('Inventario General'!$B$5:$B$304,D7)) -> 0 | F7: =IF(D7="","",SUMIF('Inventario General'!$B$5:$B$304,D7,'Inventario General'!$N$5:$N$304)) -> 0
A8: Activos a renovar (vida útil agotada) | B8: =COUNTIF('Inventario General'!$W$5:$W$304,"Renovar") -> 0 | D8: =IF(Listas!A6="","",Listas!A6) -> Tablet | E8: =IF(D8="","",COUNTIF('Inventario General'!$B$5:$B$304,D8)) -> 0 | F8: =IF(D8="","",SUMIF('Inventario General'!$B$5:$B$304,D8,'Inventario General'!$N$5:$N$304)) -> 0
A9: Activos próximos a renovar | B9: =COUNTIF('Inventario General'!$W$5:$W$304,"Próximo a renovar") -> 1 | D9: =IF(Listas!A7="","",Listas!A7) -> Servidor | E9: =IF(D9="","",COUNTIF('Inventario General'!$B$5:$B$304,D9)) -> 1 | F9: =IF(D9="","",SUMIF('Inventario General'!$B$5:$B$304,D9,'Inventario General'!$N$5:$N$304)) -> 28500
A10: Licencias vencidas | B10: =COUNTIF('Software y Licencias'!$L$5:$L$204,"Vencida") -> 0 | D10: =IF(Listas!A8="","",Listas!A8) -> NAS / Almacenamiento | E10: =IF(D10="","",COUNTIF('Inventario General'!$B$5:$B$304,D10)) -> 0 | F10: =IF(D10="","",SUMIF('Inventario General'!$B$5:$B$304,D10,'Inventario General'!$N$5:$N$304)) -> 0
A11: Licencias por vencer | B11: =COUNTIF('Software y Licencias'!$L$5:$L$204,"Por vencer") -> 1 | D11: =IF(Listas!A9="","",Listas!A9) -> Switch | E11: =IF(D11="","",COUNTIF('Inventario General'!$B$5:$B$304,D11)) -> 1 | F11: =IF(D11="","",SUMIF('Inventario General'!$B$5:$B$304,D11,'Inventario General'!$N$5:$N$304)) -> 6200
A12: Mantenimientos pendientes o en proceso | B12: =COUNTIF(Mantenimiento!$L$5:$L$204,"Pendiente")+COUNTIF(Mantenimiento!$L$5:$L$204,"En proceso") -> 0 | D12: =IF(Listas!A10="","",Listas!A10) -> Router | E12: =IF(D12="","",COUNTIF('Inventario General'!$B$5:$B$304,D12)) -> 0 | F12: =IF(D12="","",SUMIF('Inventario General'!$B$5:$B$304,D12,'Inventario General'!$N$5:$N$304)) -> 0
D13: =IF(Listas!A11="","",Listas!A11) -> Firewall | E13: =IF(D13="","",COUNTIF('Inventario General'!$B$5:$B$304,D13)) -> 0 | F13: =IF(D13="","",SUMIF('Inventario General'!$B$5:$B$304,D13,'Inventario General'!$N$5:$N$304)) -> 0
D14: =IF(Listas!A12="","",Listas!A12) -> Access Point | E14: =IF(D14="","",COUNTIF('Inventario General'!$B$5:$B$304,D14)) -> 0 | F14: =IF(D14="","",SUMIF('Inventario General'!$B$5:$B$304,D14,'Inventario General'!$N$5:$N$304)) -> 0
A15: Activos por estado | B15: Cantidad | D15: =IF(Listas!A13="","",Listas!A13) -> Impresora | E15: =IF(D15="","",COUNTIF('Inventario General'!$B$5:$B$304,D15)) -> 0 | F15: =IF(D15="","",SUMIF('Inventario General'!$B$5:$B$304,D15,'Inventario General'!$N$5:$N$304)) -> 0
A16: =IF(Listas!B2="","",Listas!B2) -> Operativo | B16: =IF(A16="","",COUNTIF('Inventario General'!$Q$5:$Q$304,A16)) -> 4 | D16: =IF(Listas!A14="","",Listas!A14) -> Multifuncional | E16: =IF(D16="","",COUNTIF('Inventario General'!$B$5:$B$304,D16)) -> 1 | F16: =IF(D16="","",SUMIF('Inventario General'!$B$5:$B$304,D16,'Inventario General'!$N$5:$N$304)) -> 1850
A17: =IF(Listas!B3="","",Listas!B3) -> En reparación | B17: =IF(A17="","",COUNTIF('Inventario General'!$Q$5:$Q$304,A17)) -> 0 | D17: =IF(Listas!A15="","",Listas!A15) -> Escáner | E17: =IF(D17="","",COUNTIF('Inventario General'!$B$5:$B$304,D17)) -> 0 | F17: =IF(D17="","",SUMIF('Inventario General'!$B$5:$B$304,D17,'Inventario General'!$N$5:$N$304)) -> 0
A18: =IF(Listas!B4="","",Listas!B4) -> En almacén | B18: =IF(A18="","",COUNTIF('Inventario General'!$Q$5:$Q$304,A18)) -> 0 | D18: =IF(Listas!A16="","",Listas!A16) -> Monitor | E18: =IF(D18="","",COUNTIF('Inventario General'!$B$5:$B$304,D18)) -> 0 | F18: =IF(D18="","",SUMIF('Inventario General'!$B$5:$B$304,D18,'Inventario General'!$N$5:$N$304)) -> 0
A19: =IF(Listas!B5="","",Listas!B5) -> Obsoleto | B19: =IF(A19="","",COUNTIF('Inventario General'!$Q$5:$Q$304,A19)) -> 0 | D19: =IF(Listas!A17="","",Listas!A17) -> Proyector | E19: =IF(D19="","",COUNTIF('Inventario General'!$B$5:$B$304,D19)) -> 0 | F19: =IF(D19="","",SUMIF('Inventario General'!$B$5:$B$304,D19,'Inventario General'!$N$5:$N$304)) -> 0
A20: =IF(Listas!B6="","",Listas!B6) -> Dado de baja | B20: =IF(A20="","",COUNTIF('Inventario General'!$Q$5:$Q$304,A20)) -> 0 | D20: =IF(Listas!A18="","",Listas!A18) -> UPS | E20: =IF(D20="","",COUNTIF('Inventario General'!$B$5:$B$304,D20)) -> 0 | F20: =IF(D20="","",SUMIF('Inventario General'!$B$5:$B$304,D20,'Inventario General'!$N$5:$N$304)) -> 0
A21: =IF(Listas!B7="","",Listas!B7) -> Extraviado | B21: =IF(A21="","",COUNTIF('Inventario General'!$Q$5:$Q$304,A21)) -> 0 | D21: =IF(Listas!A19="","",Listas!A19) -> Teléfono IP | E21: =IF(D21="","",COUNTIF('Inventario General'!$B$5:$B$304,D21)) -> 0 | F21: =IF(D21="","",SUMIF('Inventario General'!$B$5:$B$304,D21,'Inventario General'!$N$5:$N$304)) -> 0
A22: =IF(Listas!B8="","",Listas!B8) | B22: =IF(A22="","",COUNTIF('Inventario General'!$Q$5:$Q$304,A22)) | D22: =IF(Listas!A20="","",Listas!A20) -> Cámara / CCTV | E22: =IF(D22="","",COUNTIF('Inventario General'!$B$5:$B$304,D22)) -> 0 | F22: =IF(D22="","",SUMIF('Inventario General'!$B$5:$B$304,D22,'Inventario General'!$N$5:$N$304)) -> 0
A23: =IF(Listas!B9="","",Listas!B9) | B23: =IF(A23="","",COUNTIF('Inventario General'!$Q$5:$Q$304,A23)) | D23: =IF(Listas!A21="","",Listas!A21) -> Otro | E23: =IF(D23="","",COUNTIF('Inventario General'!$B$5:$B$304,D23)) -> 0 | F23: =IF(D23="","",SUMIF('Inventario General'!$B$5:$B$304,D23,'Inventario General'!$N$5:$N$304)) -> 0
A26: Activos por área | B26: Cantidad | C26: Valor (S/)
A27: =IF(Listas!D2="","",Listas!D2) -> Dirección General | B27: =IF(A27="","",COUNTIF('Inventario General'!$G$5:$G$304,A27)) -> 0 | C27: =IF(A27="","",SUMIF('Inventario General'!$G$5:$G$304,A27,'Inventario General'!$N$5:$N$304)) -> 0
A28: =IF(Listas!D3="","",Listas!D3) -> Administración | B28: =IF(A28="","",COUNTIF('Inventario General'!$G$5:$G$304,A28)) -> 2 | C28: =IF(A28="","",SUMIF('Inventario General'!$G$5:$G$304,A28,'Inventario General'!$N$5:$N$304)) -> 5700
A29: =IF(Listas!D4="","",Listas!D4) -> Contabilidad | B29: =IF(A29="","",COUNTIF('Inventario General'!$G$5:$G$304,A29)) -> 0 | C29: =IF(A29="","",SUMIF('Inventario General'!$G$5:$G$304,A29,'Inventario General'!$N$5:$N$304)) -> 0
A30: =IF(Listas!D5="","",Listas!D5) -> Logística | B30: =IF(A30="","",COUNTIF('Inventario General'!$G$5:$G$304,A30)) -> 0 | C30: =IF(A30="","",SUMIF('Inventario General'!$G$5:$G$304,A30,'Inventario General'!$N$5:$N$304)) -> 0
A31: =IF(Listas!D6="","",Listas!D6) -> Recursos Humanos | B31: =IF(A31="","",COUNTIF('Inventario General'!$G$5:$G$304,A31)) -> 0 | C31: =IF(A31="","",SUMIF('Inventario General'!$G$5:$G$304,A31,'Inventario General'!$N$5:$N$304)) -> 0
A32: =IF(Listas!D7="","",Listas!D7) -> Tecnologías de la Información | B32: =IF(A32="","",COUNTIF('Inventario General'!$G$5:$G$304,A32)) -> 2 | C32: =IF(A32="","",SUMIF('Inventario General'!$G$5:$G$304,A32,'Inventario General'!$N$5:$N$304)) -> 34700
A33: =IF(Listas!D8="","",Listas!D8) -> Legal | B33: =IF(A33="","",COUNTIF('Inventario General'!$G$5:$G$304,A33)) -> 0 | C33: =IF(A33="","",SUMIF('Inventario General'!$G$5:$G$304,A33,'Inventario General'!$N$5:$N$304)) -> 0
A34: =IF(Listas!D9="","",Listas!D9) -> Almacén | B34: =IF(A34="","",COUNTIF('Inventario General'!$G$5:$G$304,A34)) -> 0 | C34: =IF(A34="","",SUMIF('Inventario General'!$G$5:$G$304,A34,'Inventario General'!$N$5:$N$304)) -> 0
A35: =IF(Listas!D10="","",Listas!D10) -> Atención al usuario | B35: =IF(A35="","",COUNTIF('Inventario General'!$G$5:$G$304,A35)) -> 0 | C35: =IF(A35="","",SUMIF('Inventario General'!$G$5:$G$304,A35,'Inventario General'!$N$5:$N$304)) -> 0
A36: =IF(Listas!D11="","",Listas!D11) | B36: =IF(A36="","",COUNTIF('Inventario General'!$G$5:$G$304,A36)) | C36: =IF(A36="","",SUMIF('Inventario General'!$G$5:$G$304,A36,'Inventario General'!$N$5:$N$304))
A37: =IF(Listas!D12="","",Listas!D12) | B37: =IF(A37="","",COUNTIF('Inventario General'!$G$5:$G$304,A37)) | C37: =IF(A37="","",SUMIF('Inventario General'!$G$5:$G$304,A37,'Inventario General'!$N$5:$N$304))
A38: =IF(Listas!D13="","",Listas!D13) | B38: =IF(A38="","",COUNTIF('Inventario General'!$G$5:$G$304,A38)) | C38: =IF(A38="","",SUMIF('Inventario General'!$G$5:$G$304,A38,'Inventario General'!$N$5:$N$304))

Sheet Inventario General
A1: INVENTARIO GENERAL DE ACTIVOS TIC
A2: Registre cada activo una sola vez. Columnas de encabezado gris = automáticas. Filas amarillas = ejemplos ficticios (reemplácelas).
A4: Código patrimonial / interno | B4: Tipo de activo | C4: Marca | D4: Modelo | E4: N° de serie | F4: Descripción | G4: Área / Dependencia | H4: Ubicación física | I4: Responsable / Usuario | J4: Fecha de adquisición | K4: Proveedor | L4: N° de OC / Factura | M4: Tipo de adquisición | N4: Valor de adquisición (S/) | O4: Vida útil (años) | P4: Fin de garantía | Q4: Estado | R4: Conservación | S4: Criticidad | T4: Antigüedad (años) | U4: Estado de garantía | V4: Vida útil restante (años) | W4: Situación de renovación | X4: Observaciones
A5: PAT-0001 | B5: Laptop | C5: Dell | D5: Latitude 5440 | E5: 7XK2P93 | F5: Laptop de oficina 14 pulgadas | G5: Administración | H5: Piso 2 - Oficina 204 | I5: Juan Pérez Quispe | J5: 45000 | K5: Proveedor Tecnológico S.A.C. | L5: OC-2023-0145 | M5: Compra | N5: 3850 | O5: 4 | P5: 46095 | Q5: Operativo | R5: Bueno | S5: Media | T5: =IF(J5="","",ROUND((TODAY()-J5)/365.25,1)) -> 3.6 | U5: =IF(P5="","",IF(P5>=TODAY(),"Vigente","Vencida")) -> Vencida | V5: =IF(OR(J5="",O5=""),"",ROUND(O5-T5,1)) -> 0.4 | W5: =IF(V5="","",IF(V5<=0,"Renovar",IF(V5<=Listas!$T$3,"Próximo a renovar","Vigente"))) -> Próximo a renovar | X5: FILA DE EJEMPLO: reemplazar o borrar
A6: PAT-0002 | B6: Servidor | C6: HPE | D6: ProLiant DL380 Gen11 | E6: MXQ3340R5K | F6: Servidor de archivos y respaldo | G6: Tecnologías de la Información | H6: Sala de servidores - Rack 1 | I6: Equipo de TI | J6: 45453 | K6: Proveedor Tecnológico S.A.C. | L6: OC-2024-0087 | M6: Compra | N6: 28500 | O6: 5 | P6: 47278 | Q6: Operativo | R6: Nuevo | S6: Alta | T6: =IF(J6="","",ROUND((TODAY()-J6)/365.25,1)) -> 2.4 | U6: =IF(P6="","",IF(P6>=TODAY(),"Vigente","Vencida")) -> Vigente | V6: =IF(OR(J6="",O6=""),"",ROUND(O6-T6,1)) -> 2.6 | W6: =IF(V6="","",IF(V6<=0,"Renovar",IF(V6<=Listas!$T$3,"Próximo a renovar","Vigente"))) -> Vigente | X6: FILA DE EJEMPLO
A7: PAT-0003 | B7: Switch | C7: Cisco | D7: Catalyst 9200L-24P | E7: FOC2512L0AB | F7: Switch de acceso 24 puertos PoE+ | G7: Tecnologías de la Información | H7: Sala de servidores - Rack 1 | I7: Equipo de TI | J7: 44581 | K7: Proveedor Tecnológico S.A.C. | L7: OC-2022-0012 | M7: Compra | N7: 6200 | O7: 6 | P7: 45676 | Q7: Operativo | R7: Bueno | S7: Alta | T7: =IF(J7="","",ROUND((TODAY()-J7)/365.25,1)) -> 4.8 | U7: =IF(P7="","",IF(P7>=TODAY(),"Vigente","Vencida")) -> Vencida | V7: =IF(OR(J7="",O7=""),"",ROUND(O7-T7,1)) -> 1.2 | W7: =IF(V7="","",IF(V7<=0,"Renovar",IF(V7<=Listas!$T$3,"Próximo a renovar","Vigente"))) -> Vigente | X7: FILA DE EJEMPLO
A8: PAT-0004 | B8: Multifuncional | C8: HP | D8: LaserJet Pro MFP M428fdw | E8: PHBLN12345 | F8: Multifuncional láser monocromática | G8: Administración | H8: Piso 2 - Pasillo | I8: Área de Administración | J8: 45689 | K8: Proveedor Tecnológico S.A.C. | L8: OC-2025-0031 | M8: Compra | N8: 1850 | O8: 5 | P8: 46418 | Q8: Operativo | R8: Bueno | S8: Baja | T8: =IF(J8="","",ROUND((TODAY()-J8)/365.25,1)) -> 1.7 | U8: =IF(P8="","",IF(P8>=TODAY(),"Vigente","Vencida")) -> Vigente | V8: =IF(OR(J8="",O8=""),"",ROUND(O8-T8,1)) -> 3.3 | W8: =IF(V8="","",IF(V8<=0,"Renovar",IF(V8<=Listas!$T$3,"Próximo a renovar","Vigente"))) -> Vigente | X8: FILA DE EJEMPLO
T9: =IF(J9="","",ROUND((TODAY()-J9)/365.25,1)) | U9: =IF(P9="","",IF(P9>=TODAY(),"Vigente","Vencida")) | V9: =IF(OR(J9="",O9=""),"",ROUND(O9-T9,1)) | W9: =IF(V9="","",IF(V9<=0,"Renovar",IF(V9<=Listas!$T$3,"Próximo a renovar","Vigente")))
T10: =IF(J10="","",ROUND((TODAY()-J10)/365.25,1)) | U10: =IF(P10="","",IF(P10>=TODAY(),"Vigente","Vencida")) | V10: =IF(OR(J10="",O10=""),"",ROUND(O10-T10,1)) | W10: =IF(V10="","",IF(V10<=0,"Renovar",IF(V10<=Listas!$T$3,"Próximo a renovar","Vigente")))
T11: =IF(J11="","",ROUND((TODAY()-J11)/365.25,1)) | U11: =IF(P11="","",IF(P11>=TODAY(),"Vigente","Vencida")) | V11: =IF(OR(J11="",O11=""),"",ROUND(O11-T11,1)) | W11: =IF(V11="","",IF(V11<=0,"Renovar",IF(V11<=Listas!$T$3,"Próximo a renovar","Vigente")))
T12: =IF(J12="","",ROUND((TODAY()-J12)/365.25,1)) | U12: =IF(P12="","",IF(P12>=TODAY(),"Vigente","Vencida")) | V12: =IF(OR(J12="",O12=""),"",ROUND(O12-T12,1)) | W12: =IF(V12="","",IF(V12<=0,"Renovar",IF(V12<=Listas!$T$3,"Próximo a renovar","Vigente")))
T13: =IF(J13="","",ROUND((TODAY()-J13)/365.25,1)) | U13: =IF(P13="","",IF(P13>=TODAY(),"Vigente","Vencida")) | V13: =IF(OR(J13="",O13=""),"",ROUND(O13-T13,1)) | W13: =IF(V13="","",IF(V13<=0,"Renovar",IF(V13<=Listas!$T$3,"Próximo a renovar","Vigente")))
T14: =IF(J14="","",ROUND((TODAY()-J14)/365.25,1)) | U14: =IF(P14="","",IF(P14>=TODAY(),"Vigente","Vencida")) | V14: =IF(OR(J14="",O14=""),"",ROUND(O14-T14,1)) | W14: =IF(V14="","",IF(V14<=0,"Renovar",IF(V14<=Listas!$T$3,"Próximo a renovar","Vigente")))
T15: =IF(J15="","",ROUND((TODAY()-J15)/365.25,1)) | U15: =IF(P15="","",IF(P15>=TODAY(),"Vigente","Vencida")) | V15: =IF(OR(J15="",O15=""),"",ROUND(O15-T15,1)) | W15: =IF(V15="","",IF(V15<=0,"Renovar",IF(V15<=Listas!$T$3,"Próximo a renovar","Vigente")))
T16: =IF(J16="","",ROUND((TODAY()-J16)/365.25,1)) | U16: =IF(P16="","",IF(P16>=TODAY(),"Vigente","Vencida")) | V16: =IF(OR(J16="",O16=""),"",ROUND(O16-T16,1)) | W16: =IF(V16="","",IF(V16<=0,"Renovar",IF(V16<=Listas!$T$3,"Próximo a renovar","Vigente")))
T17: =IF(J17="","",ROUND((TODAY()-J17)/365.25,1)) | U17: =IF(P17="","",IF(P17>=TODAY(),"Vigente","Vencida")) | V17: =IF(OR(J17="",O17=""),"",ROUND(O17-T17,1)) | W17: =IF(V17="","",IF(V17<=0,"Renovar",IF(V17<=Listas!$T$3,"Próximo a renovar","Vigente")))
T18: =IF(J18="","",ROUND((TODAY()-J18)/365.25,1)) | U18: =IF(P18="","",IF(P18>=TODAY(),"Vigente","Vencida")) | V18: =IF(OR(J18="",O18=""),"",ROUND(O18-T18,1)) | W18: =IF(V18="","",IF(V18<=0,"Renovar",IF(V18<=Listas!$T$3,"Próximo a renovar","Vigente")))
T19: =IF(J19="","",ROUND((TODAY()-J19)/365.25,1)) | U19: =IF(P19="","",IF(P19>=TODAY(),"Vigente","Vencida")) | V19: =IF(OR(J19="",O19=""),"",ROUND(O19-T19,1)) | W19: =IF(V19="","",IF(V19<=0,"Renovar",IF(V19<=Listas!$T$3,"Próximo a renovar","Vigente")))
T20: =IF(J20="","",ROUND((TODAY()-J20)/365.25,1)) | U20: =IF(P20="","",IF(P20>=TODAY(),"Vigente","Vencida")) | V20: =IF(OR(J20="",O20=""),"",ROUND(O20-T20,1)) | W20: =IF(V20="","",IF(V20<=0,"Renovar",IF(V20<=Listas!$T$3,"Próximo a renovar","Vigente")))
... T304: =IF(J304="","",ROUND((TODAY()-J304)/365.25,1)) | U304: =IF(P304="","",IF(P304>=TODAY(),"Vigente","Vencida")) | V304: =IF(OR(J304="",O304=""),"",ROUND(O304-T304,1)) | W304: =IF(V304="","",IF(V304<=0,"Renovar",IF(V304<=Listas!$T$3,"Próximo a renovar","Vigente")))

Sheet Ficha Individual
A1: FICHA TÉCNICA DE ACTIVO TIC
A3: Código del activo: | B3: PAT-0001 | C3: ← Elija o escriba el código; la ficha se completa sola.
A5: 1. IDENTIFICACIÓN
A6: Tipo de activo | B6: =IF($B$3="","",IFERROR(IF(INDEX('Inventario General'!$B$5:$B$304,MATCH($B$3,'Inventario General'!$A$5:$A$304,0))="","",INDEX('Inventario General'!$B$5:$B$304,MATCH($B$3,'Inventario General'!$A$5:$A$304,0))),"No está en el inventario")) -> Laptop | C6: Marca | D6: =IF($B$3="","",IFERROR(IF(INDEX('Inventario General'!$C$5:$C$304,MATCH($B$3,'Inventario General'!$A$5:$A$304,0))="","",INDEX('Inventario General'!$C$5:$C$304,MATCH($B$3,'Inventario General'!$A$5:$A$304,0))),"No está en el inventario")) -> Dell
A7: Modelo | B7: =IF($B$3="","",IFERROR(IF(INDEX('Inventario General'!$D$5:$D$304,MATCH($B$3,'Inventario General'!$A$5:$A$304,0))="","",INDEX('Inventario General'!$D$5:$D$304,MATCH($B$3,'Inventario General'!$A$5:$A$304,0))),"No está en el inventario")) -> Latitude 5440 | C7: N° de serie | D7: =IF($B$3="","",IFERROR(IF(INDEX('Inventario General'!$E$5:$E$304,MATCH($B$3,'Inventario General'!$A$5:$A$304,0))="","",INDEX('Inventario General'!$E$5:$E$304,MATCH($B$3,'Inventario General'!$A$5:$A$304,0))),"No está en el inventario")) -> 7XK2P93
A8: Descripción | B8: =IF($B$3="","",IFERROR(IF(INDEX('Inventario General'!$F$5:$F$304,MATCH($B$3,'Inventario General'!$A$5:$A$304,0))="","",INDEX('Inventario General'!$F$5:$F$304,MATCH($B$3,'Inventario General'!$A$5:$A$304,0))),"No está en el inventario")) -> Laptop de oficina 14 pulgadas | C8: Estado | D8: =IF($B$3="","",IFERROR(IF(INDEX('Inventario General'!$Q$5:$Q$304,MATCH($B$3,'Inventario General'!$A$5:$A$304,0))="","",INDEX('Inventario General'!$Q$5:$Q$304,MATCH($B$3,'Inventario General'!$A$5:$A$304,0))),"No está en el inventario")) -> Operativo
A10: 2. UBICACIÓN Y RESPONSABLE
A11: Área / Dependencia | B11: =IF($B$3="","",IFERROR(IF(INDEX('Inventario General'!$G$5:$G$304,MATCH($B$3,'Inventario General'!$A$5:$A$304,0))="","",INDEX('Inventario General'!$G$5:$G$304,MATCH($B$3,'Inventario General'!$A$5:$A$304,0))),"No está en el inventario")) -> Administración | C11: Ubicación física | D11: =IF($B$3="","",IFERROR(IF(INDEX('Inventario General'!$H$5:$H$304,MATCH($B$3,'Inventario General'!$A$5:$A$304,0))="","",INDEX('Inventario General'!$H$5:$H$304,MATCH($B$3,'Inventario General'!$A$5:$A$304,0))),"No está en el inventario")) -> Piso 2 - Oficina 204
A12: Responsable / Usuario | B12: =IF($B$3="","",IFERROR(IF(INDEX('Inventario General'!$I$5:$I$304,MATCH($B$3,'Inventario General'!$A$5:$A$304,0))="","",INDEX('Inventario General'!$I$5:$I$304,MATCH($B$3,'Inventario General'!$A$5:$A$304,0))),"No está en el inventario")) -> Juan Pérez Quispe | C12: Criticidad | D12: =IF($B$3="","",IFERROR(IF(INDEX('Inventario General'!$S$5:$S$304,MATCH($B$3,'Inventario General'!$A$5:$A$304,0))="","",INDEX('Inventario General'!$S$5:$S$304,MATCH($B$3,'Inventario General'!$A$5:$A$304,0))),"No está en el inventario")) -> Media
A14: 3. ADQUISICIÓN
A15: Fecha de adquisición | B15: =IF($B$3="","",IFERROR(IF(INDEX('Inventario General'!$J$5:$J$304,MATCH($B$3,'Inventario General'!$A$5:$A$304,0))="","",INDEX('Inventario General'!$J$5:$J$304,MATCH($B$3,'Inventario General'!$A$5:$A$304,0))),"No está en el inventario")) -> 45000 | C15: Proveedor | D15: =IF($B$3="","",IFERROR(IF(INDEX('Inventario General'!$K$5:$K$304,MATCH($B$3,'Inventario General'!$A$5:$A$304,0))="","",INDEX('Inventario General'!$K$5:$K$304,MATCH($B$3,'Inventario General'!$A$5:$A$304,0))),"No está en el inventario")) -> Proveedor Tecnológico S.A.C.
A16: N° de OC / Factura | B16: =IF($B$3="","",IFERROR(IF(INDEX('Inventario General'!$L$5:$L$304,MATCH($B$3,'Inventario General'!$A$5:$A$304,0))="","",INDEX('Inventario General'!$L$5:$L$304,MATCH($B$3,'Inventario General'!$A$5:$A$304,0))),"No está en el inventario")) -> OC-2023-0145 | C16: Tipo de adquisición | D16: =IF($B$3="","",IFERROR(IF(INDEX('Inventario General'!$M$5:$M$304,MATCH($B$3,'Inventario General'!$A$5:$A$304,0))="","",INDEX('Inventario General'!$M$5:$M$304,MATCH($B$3,'Inventario General'!$A$5:$A$304,0))),"No está en el inventario")) -> Compra
A17: Valor de adquisición | B17: =IF($B$3="","",IFERROR(IF(INDEX('Inventario General'!$N$5:$N$304,MATCH($B$3,'Inventario General'!$A$5:$A$304,0))="","",INDEX('Inventario General'!$N$5:$N$304,MATCH($B$3,'Inventario General'!$A$5:$A$304,0))),"No está en el inventario")) -> 3850 | C17: Conservación | D17: =IF($B$3="","",IFERROR(IF(INDEX('Inventario General'!$R$5:$R$304,MATCH($B$3,'Inventario General'!$A$5:$A$304,0))="","",INDEX('Inventario General'!$R$5:$R$304,MATCH($B$3,'Inventario General'!$A$5:$A$304,0))),"No está en el inventario")) -> Bueno
A19: 4. GARANTÍA Y CICLO DE VIDA
A20: Fin de garantía | B20: =IF($B$3="","",IFERROR(IF(INDEX('Inventario General'!$P$5:$P$304,MATCH($B$3,'Inventario General'!$A$5:$A$304,0))="","",INDEX('Inventario General'!$P$5:$P$304,MATCH($B$3,'Inventario General'!$A$5:$A$304,0))),"No está en el inventario")) -> 46095 | C20: Estado de garantía | D20: =IF($B$3="","",IFERROR(IF(INDEX('Inventario General'!$U$5:$U$304,MATCH($B$3,'Inventario General'!$A$5:$A$304,0))="","",INDEX('Inventario General'!$U$5:$U$304,MATCH($B$3,'Inventario General'!$A$5:$A$304,0))),"No está en el inventario")) -> Vencida
A21: Vida útil (años) | B21: =IF($B$3="","",IFERROR(IF(INDEX('Inventario General'!$O$5:$O$304,MATCH($B$3,'Inventario General'!$A$5:$A$304,0))="","",INDEX('Inventario General'!$O$5:$O$304,MATCH($B$3,'Inventario General'!$A$5:$A$304,0))),"No está en el inventario")) -> 4 | C21: Antigüedad (años) | D21: =IF($B$3="","",IFERROR(IF(INDEX('Inventario General'!$T$5:$T$304,MATCH($B$3,'Inventario General'!$A$5:$A$304,0))="","",INDEX('Inventario General'!$T$5:$T$304,MATCH($B$3,'Inventario General'!$A$5:$A$304,0))),"No está en el inventario")) -> 3.6
A22: Vida útil restante (años) | B22: =IF($B$3="","",IFERROR(IF(INDEX('Inventario General'!$V$5:$V$304,MATCH($B$3,'Inventario General'!$A$5:$A$304,0))="","",INDEX('Inventario General'!$V$5:$V$304,MATCH($B$3,'Inventario General'!$A$5:$A$304,0))),"No está en el inventario")) -> 0.4 | C22: Situación de renovación | D22: =IF($B$3="","",IFERROR(IF(INDEX('Inventario General'!$W$5:$W$304,MATCH($B$3,'Inventario General'!$A$5:$A$304,0))="","",INDEX('Inventario General'!$W$5:$W$304,MATCH($B$3,'Inventario General'!$A$5:$A$304,0))),"No está en el inventario")) -> Próximo a renovar
A24: 5. CARACTERÍSTICAS TÉCNICAS (si es equipo de cómputo)
A25: Procesador | B25: =IF($B$3="","",IFERROR(IF(INDEX('Equipos de Cómputo'!$F$5:$F$204,MATCH($B$3,'Equipos de Cómputo'!$A$5:$A$204,0))="","",INDEX('Equipos de Cómputo'!$F$5:$F$204,MATCH($B$3,'Equipos de Cómputo'!$A$5:$A$204,0))),"—")) -> Intel Core i7-1355U | C25: Memoria RAM (GB) | D25: =IF($B$3="","",IFERROR(IF(INDEX('Equipos de Cómputo'!$I$5:$I$204,MATCH($B$3,'Equipos de Cómputo'!$A$5:$A$204,0))="","",INDEX('Equipos de Cómputo'!$I$5:$I$204,MATCH($B$3,'Equipos de Cómputo'!$A$5:$A$204,0))),"—")) -> 16
A26: Tipo de almacenamiento | B26: =IF($B$3="","",IFERROR(IF(INDEX('Equipos de Cómputo'!$K$5:$K$204,MATCH($B$3,'Equipos de Cómputo'!$A$5:$A$204,0))="","",INDEX('Equipos de Cómputo'!$K$5:$K$204,MATCH($B$3,'Equipos de Cómputo'!$A$5:$A$204,0))),"—")) -> SSD | C26: Capacidad (GB) | D26: =IF($B$3="","",IFERROR(IF(INDEX('Equipos de Cómputo'!$L$5:$L$204,MATCH($B$3,'Equipos de Cómputo'!$A$5:$A$204,0))="","",INDEX('Equipos de Cómputo'!$L$5:$L$204,MATCH($B$3,'Equipos de Cómputo'!$A$5:$A$204,0))),"—")) -> 512
A27: Sistema operativo | B27: =IF($B$3="","",IFERROR(IF(INDEX('Equipos de Cómputo'!$O$5:$O$204,MATCH($B$3,'Equipos de Cómputo'!$A$5:$A$204,0))="","",INDEX('Equipos de Cómputo'!$O$5:$O$204,MATCH($B$3,'Equipos de Cómputo'!$A$5:$A$204,0))),"—")) -> Windows 11 Pro | C27: Nombre de equipo | D27: =IF($B$3="","",IFERROR(IF(INDEX('Equipos de Cómputo'!$Q$5:$Q$204,MATCH($B$3,'Equipos de Cómputo'!$A$5:$A$204,0))="","",INDEX('Equipos de Cómputo'!$Q$5:$Q$204,MATCH($B$3,'Equipos de Cómputo'!$A$5:$A$204,0))),"—")) -> ADM-LT-001
A28: Dirección IP | B28: =IF($B$3="","",IFERROR(IF(INDEX('Equipos de Cómputo'!$R$5:$R$204,MATCH($B$3,'Equipos de Cómputo'!$A$5:$A$204,0))="","",INDEX('Equipos de Cómputo'!$R$5:$R$204,MATCH($B$3,'Equipos de Cómputo'!$A$5:$A$204,0))),"—")) -> 192.168.10.45 | C28: Dirección MAC | D28: =IF($B$3="","",IFERROR(IF(INDEX('Equipos de Cómputo'!$S$5:$S$204,MATCH($B$3,'Equipos de Cómputo'!$A$5:$A$204,0))="","",INDEX('Equipos de Cómputo'!$S$5:$S$204,MATCH($B$3,'Equipos de Cómputo'!$A$5:$A$204,0))),"—")) -> A4:BB:6D:12:34:56
A30: 6. HISTORIAL DE MANTENIMIENTO
A31: N° de mantenimientos | B31: =IF($B$3="","",COUNTIF(Mantenimiento!$B$5:$B$204,$B$3)) -> 1 | C31: Costo acumulado | D31: =IF($B$3="","",SUMIF(Mantenimiento!$B$5:$B$204,$B$3,Mantenimiento!$I$5:$I$204)) -> 80
A32: Último mantenimiento | B32: =IF($B$3="","",IF(COUNTIF(Mantenimiento!$B$5:$B$204,$B$3)=0,"Sin registros",SUMPRODUCT(MAX((Mantenimiento!$B$5:$B$204=$B$3)*Mantenimiento!$E$5:$E$204)))) -> 46254 | C32: Observaciones | D32: =IF($B$3="","",IFERROR(IF(INDEX('Inventario General'!$X$5:$X$304,MATCH($B$3,'Inventario General'!$A$5:$A$304,0))="","",INDEX('Inventario General'!$X$5:$X$304,MATCH($B$3,'Inventario General'!$A$5:$A$304,0))),"No está en el inventario")) -> FILA DE EJEMPLO: reemplazar o borrar
A37: ____________________________ | B37: ____________________________ | C37: ____________________________
A38: Elaborado por (TI) | B38: Responsable del activo | C38: Jefe / Visto bueno
A39: Fecha: ____ / ____ / ________ | B39: Fecha: ____ / ____ / ________ | C39: Fecha: ____ / ____ / ________

Sheet Equipos de Cómputo
A1: FICHA TÉCNICA – EQUIPOS DE CÓMPUTO
A2: Laptops, PC, all-in-one, workstations y tablets. Elija el código (debe existir en 'Inventario General'); marca, modelo y responsable se traen solos.
A4: Código patrimonial | B4: Marca | C4: Modelo | D4: Responsable | E4: Tipo de equipo | F4: Procesador | G4: Velocidad / Generación | H4: N° de núcleos | I4: Memoria RAM (GB) | J4: Tipo de RAM | K4: Tipo de almacenamiento | L4: Capacidad de almacenamiento (GB) | M4: Tarjeta gráfica | N4: Pantalla (pulgadas) | O4: Sistema operativo | P4: Versión del SO | Q4: Nombre de equipo (hostname) | R4: Dirección IP | S4: Dirección MAC | T4: Dominio / Grupo de trabajo | U4: Antivirus / EDR | V4: Disco cifrado | W4: Puertos principales | X4: Accesorios incluidos | Y4: Observaciones
A5: PAT-0001 | B5: =IF($A5="","",IFERROR(INDEX('Inventario General'!$C$5:$C$304,MATCH($A5,'Inventario General'!$A$5:$A$304,0))&"","No está en el inventario")) -> Dell | C5: =IF($A5="","",IFERROR(INDEX('Inventario General'!$D$5:$D$304,MATCH($A5,'Inventario General'!$A$5:$A$304,0))&"","No está en el inventario")) -> Latitude 5440 | D5: =IF($A5="","",IFERROR(INDEX('Inventario General'!$I$5:$I$304,MATCH($A5,'Inventario General'!$A$5:$A$304,0))&"","No está en el inventario")) -> Juan Pérez Quispe | E5: Laptop | F5: Intel Core i7-1355U | G5: 1.7 GHz (13.ª gen.) | H5: 10 | I5: 16 | J5: DDR5 | K5: SSD | L5: 512 | M5: Intel Iris Xe | N5: 14 | O5: Windows 11 Pro | P5: 23H2 | Q5: ADM-LT-001 | R5: 192.168.10.45 | S5: A4:BB:6D:12:34:56 | T5: empresa.local | U5: Microsoft Defender | V5: Sí | W5: 2 USB-C, 2 USB-A, HDMI, RJ-45 | X5: Cargador, mochila | Y5: FILA DE EJEMPLO
B6: =IF($A6="","",IFERROR(INDEX('Inventario General'!$C$5:$C$304,MATCH($A6,'Inventario General'!$A$5:$A$304,0))&"","No está en el inventario")) | C6: =IF($A6="","",IFERROR(INDEX('Inventario General'!$D$5:$D$304,MATCH($A6,'Inventario General'!$A$5:$A$304,0))&"","No está en el inventario")) | D6: =IF($A6="","",IFERROR(INDEX('Inventario General'!$I$5:$I$304,MATCH($A6,'Inventario General'!$A$5:$A$304,0))&"","No está en el inventario"))
B7: =IF($A7="","",IFERROR(INDEX('Inventario General'!$C$5:$C$304,MATCH($A7,'Inventario General'!$A$5:$A$304,0))&"","No está en el inventario")) | C7: =IF($A7="","",IFERROR(INDEX('Inventario General'!$D$5:$D$304,MATCH($A7,'Inventario General'!$A$5:$A$304,0))&"","No está en el inventario")) | D7: =IF($A7="","",IFERROR(INDEX('Inventario General'!$I$5:$I$304,MATCH($A7,'Inventario General'!$A$5:$A$304,0))&"","No está en el inventario"))
B8: =IF($A8="","",IFERROR(INDEX('Inventario General'!$C$5:$C$304,MATCH($A8,'Inventario General'!$A$5:$A$304,0))&"","No está en el inventario")) | C8: =IF($A8="","",IFERROR(INDEX('Inventario General'!$D$5:$D$304,MATCH($A8,'Inventario General'!$A$5:$A$304,0))&"","No está en el inventario")) | D8: =IF($A8="","",IFERROR(INDEX('Inventario General'!$I$5:$I$304,MATCH($A8,'Inventario General'!$A$5:$A$304,0))&"","No está en el inventario"))
B9: =IF($A9="","",IFERROR(INDEX('Inventario General'!$C$5:$C$304,MATCH($A9,'Inventario General'!$A$5:$A$304,0))&"","No está en el inventario")) | C9: =IF($A9="","",IFERROR(INDEX('Inventario General'!$D$5:$D$304,MATCH($A9,'Inventario General'!$A$5:$A$304,0))&"","No está en el inventario")) | D9: =IF($A9="","",IFERROR(INDEX('Inventario General'!$I$5:$I$304,MATCH($A9,'Inventario General'!$A$5:$A$304,0))&"","No está en el inventario"))
B10: =IF($A10="","",IFERROR(INDEX('Inventario General'!$C$5:$C$304,MATCH($A10,'Inventario General'!$A$5:$A$304,0))&"","No está en el inventario")) | C10: =IF($A10="","",IFERROR(INDEX('Inventario General'!$D$5:$D$304,MATCH($A10,'Inventario General'!$A$5:$A$304,0))&"","No está en el inventario")) | D10: =IF($A10="","",IFERROR(INDEX('Inventario General'!$I$5:$I$304,MATCH($A10,'Inventario General'!$A$5:$A$304,0))&"","No está en el inventario"))
B11: =IF($A11="","",IFERROR(INDEX('Inventario General'!$C$5:$C$304,MATCH($A11,'Inventario General'!$A$5:$A$304,0))&"","No está en el inventario")) | C11: =IF($A11="","",IFERROR(INDEX('Inventario General'!$D$5:$D$304,MATCH($A11,'Inventario General'!$A$5:$A$304,0))&"","No está en el inventario")) | D11: =IF($A11="","",IFERROR(INDEX('Inventario General'!$I$5:$I$304,MATCH($A11,'Inventario General'!$A$5:$A$304,0))&"","No está en el inventario"))
B12: =IF($A12="","",IFERROR(INDEX('Inventario General'!$C$5:$C$304,MATCH($A12,'Inventario General'!$A$5:$A$304,0))&"","No está en el inventario")) | C12: =IF($A12="","",IFERROR(INDEX('Inventario General'!$D$5:$D$304,MATCH($A12,'Inventario General'!$A$5:$A$304,0))&"","No está en el inventario")) | D12: =IF($A12="","",IFERROR(INDEX('Inventario General'!$I$5:$I$304,MATCH($A12,'Inventario General'!$A$5:$A$304,0))&"","No está en el inventario"))
B13: =IF($A13="","",IFERROR(INDEX('Inventario General'!$C$5:$C$304,MATCH($A13,'Inventario General'!$A$5:$A$304,0))&"","No está en el inventario")) | C13: =IF($A13="","",IFERROR(INDEX('Inventario General'!$D$5:$D$304,MATCH($A13,'Inventario General'!$A$5:$A$304,0))&"","No está en el inventario")) | D13: =IF($A13="","",IFERROR(INDEX('Inventario General'!$I$5:$I$304,MATCH($A13,'Inventario General'!$A$5:$A$304,0))&"","No está en el inventario"))
B14: =IF($A14="","",IFERROR(INDEX('Inventario General'!$C$5:$C$304,MATCH($A14,'Inventario General'!$A$5:$A$304,0))&"","No está en el inventario")) | C14: =IF($A14="","",IFERROR(INDEX('Inventario General'!$D$5:$D$304,MATCH($A14,'Inventario General'!$A$5:$A$304,0))&"","No está en el inventario")) | D14: =IF($A14="","",IFERROR(INDEX('Inventario General'!$I$5:$I$304,MATCH($A14,'Inventario General'!$A$5:$A$304,0))&"","No está en el inventario"))
B15: =IF($A15="","",IFERROR(INDEX('Inventario General'!$C$5:$C$304,MATCH($A15,'Inventario General'!$A$5:$A$304,0))&"","No está en el inventario")) | C15: =IF($A15="","",IFERROR(INDEX('Inventario General'!$D$5:$D$304,MATCH($A15,'Inventario General'!$A$5:$A$304,0))&"","No está en el inventario")) | D15: =IF($A15="","",IFERROR(INDEX('Inventario General'!$I$5:$I$304,MATCH($A15,'Inventario General'!$A$5:$A$304,0))&"","No está en el inventario"))
B16: =IF($A16="","",IFERROR(INDEX('Inventario General'!$C$5:$C$304,MATCH($A16,'Inventario General'!$A$5:$A$304,0))&"","No está en el inventario")) | C16: =IF($A16="","",IFERROR(INDEX('Inventario General'!$D$5:$D$304,MATCH($A16,'Inventario General'!$A$5:$A$304,0))&"","No está en el inventario")) | D16: =IF($A16="","",IFERROR(INDEX('Inventario General'!$I$5:$I$304,MATCH($A16,'Inventario General'!$A$5:$A$304,0))&"","No está en el inventario"))
B17: =IF($A17="","",IFERROR(INDEX('Inventario General'!$C$5:$C$304,MATCH($A17,'Inventario General'!$A$5:$A$304,0))&"","No está en el inventario")) | C17: =IF($A17="","",IFERROR(INDEX('Inventario General'!$D$5:$D$304,MATCH($A17,'Inventario General'!$A$5:$A$304,0))&"","No está en el inventario")) | D17: =IF($A17="","",IFERROR(INDEX('Inventario General'!$I$5:$I$304,MATCH($A17,'Inventario General'!$A$5:$A$304,0))&"","No está en el inventario"))
... B204: =IF($A204="","",IFERROR(INDEX('Inventario General'!$C$5:$C$304,MATCH($A204,'Inventario General'!$A$5:$A$304,0))&"","No está en el inventario")) | C204: =IF($A204="","",IFERROR(INDEX('Inventario General'!$D$5:$D$304,MATCH($A204,'Inventario General'!$A$5:$A$304,0))&"","No está en el inventario")) | D204: =IF($A204="","",IFERROR(INDEX('Inventario General'!$I$5:$I$304,MATCH($A204,'Inventario General'!$A$5:$A$304,0))&"","No está en el inventario"))

Sheet Servidores
A1: FICHA TÉCNICA – SERVIDORES
A2: Servidores físicos y virtuales. Elija el código del inventario; los datos generales se traen solos.
A4: Código patrimonial | B4: Marca | C4: Modelo | D4: Responsable | E4: Tipo de servidor | F4: Rol principal | G4: Procesador | H4: N° de procesadores | I4: Núcleos totales | J4: Memoria RAM (GB) | K4: Almacenamiento total (TB) | L4: Configuración RAID | M4: N° de fuentes de poder | N4: Sistema operativo | O4: Nombre de equipo (hostname) | P4: Dirección IP | Q4: Hipervisor / Virtualización | R4: N° de máquinas virtuales | S4: Ubicación en rack (U) | T4: Consumo (W) | U4: UPS asociado (código) | V4: Frecuencia de respaldo | W4: Último respaldo | X4: Observaciones
A5: PAT-0002 | B5: =IF($A5="","",IFERROR(INDEX('Inventario General'!$C$5:$C$304,MATCH($A5,'Inventario General'!$A$5:$A$304,0))&"","No está en el inventario")) -> HPE | C5: =IF($A5="","",IFERROR(INDEX('Inventario General'!$D$5:$D$304,MATCH($A5,'Inventario General'!$A$5:$A$304,0))&"","No está en el inventario")) -> ProLiant DL380 Gen11 | D5: =IF($A5="","",IFERROR(INDEX('Inventario General'!$I$5:$I$304,MATCH($A5,'Inventario General'!$A$5:$A$304,0))&"","No está en el inventario")) -> Equipo de TI | E5: Rack | F5: Archivos | G5: Intel Xeon Silver 4410Y | H5: 1 | I5: 12 | J5: 64 | K5: 8 | L5: RAID 5 | M5: 2 | N5: Windows Server 2022 | O5: SRV-FILE-01 | P5: 192.168.10.10 | Q5: Hyper-V | R5: 3 | S5: U10–U12 (2U) | T5: 800 | U5: UPS-01 | V5: Diario | W5: 46295 | X5: FILA DE EJEMPLO
B6: =IF($A6="","",IFERROR(INDEX('Inventario General'!$C$5:$C$304,MATCH($A6,'Inventario General'!$A$5:$A$304,0))&"","No está en el inventario")) | C6: =IF($A6="","",IFERROR(INDEX('Inventario General'!$D$5:$D$304,MATCH($A6,'Inventario General'!$A$5:$A$304,0))&"","No está en el inventario")) | D6: =IF($A6="","",IFERROR(INDEX('Inventario General'!$I$5:$I$304,MATCH($A6,'Inventario General'!$A$5:$A$304,0))&"","No está en el inventario"))
B7: =IF($A7="","",IFERROR(INDEX('Inventario General'!$C$5:$C$304,MATCH($A7,'Inventario General'!$A$5:$A$304,0))&"","No está en el inventario")) | C7: =IF($A7="","",IFERROR(INDEX('Inventario General'!$D$5:$D$304,MATCH($A7,'Inventario General'!$A$5:$A$304,0))&"","No está en el inventario")) | D7: =IF($A7="","",IFERROR(INDEX('Inventario General'!$I$5:$I$304,MATCH($A7,'Inventario General'!$A$5:$A$304,0))&"","No está en el inventario"))
B8: =IF($A8="","",IFERROR(INDEX('Inventario General'!$C$5:$C$304,MATCH($A8,'Inventario General'!$A$5:$A$304,0))&"","No está en el inventario")) | C8: =IF($A8="","",IFERROR(INDEX('Inventario General'!$D$5:$D$304,MATCH($A8,'Inventario General'!$A$5:$A$304,0))&"","No está en el inventario")) | D8: =IF($A8="","",IFERROR(INDEX('Inventario General'!$I$5:$I$304,MATCH($A8,'Inventario General'!$A$5:$A$304,0))&"","No está en el inventario"))
B9: =IF($A9="","",IFERROR(INDEX('Inventario General'!$C$5:$C$304,MATCH($A9,'Inventario General'!$A$5:$A$304,0))&"","No está en el inventario")) | C9: =IF($A9="","",IFERROR(INDEX('Inventario General'!$D$5:$D$304,MATCH($A9,'Inventario General'!$A$5:$A$304,0))&"","No está en el inventario")) | D9: =IF($A9="","",IFERROR(INDEX('Inventario General'!$I$5:$I$304,MATCH($A9,'Inventario General'!$A$5:$A$304,0))&"","No está en el inventario"))
B10: =IF($A10="","",IFERROR(INDEX('Inventario General'!$C$5:$C$304,MATCH($A10,'Inventario General'!$A$5:$A$304,0))&"","No está en el inventario")) | C10: =IF($A10="","",IFERROR(INDEX('Inventario General'!$D$5:$D$304,MATCH($A10,'Inventario General'!$A$5:$A$304,0))&"","No está en el inventario")) | D10: =IF($A10="","",IFERROR(INDEX('Inventario General'!$I$5:$I$304,MATCH($A10,'Inventario General'!$A$5:$A$304,0))&"","No está en el inventario"))
B11: =IF($A11="","",IFERROR(INDEX('Inventario General'!$C$5:$C$304,MATCH($A11,'Inventario General'!$A$5:$A$304,0))&"","No está en el inventario")) | C11: =IF($A11="","",IFERROR(INDEX('Inventario General'!$D$5:$D$304,MATCH($A11,'Inventario General'!$A$5:$A$304,0))&"","No está en el inventario")) | D11: =IF($A11="","",IFERROR(INDEX('Inventario General'!$I$5:$I$304,MATCH($A11,'Inventario General'!$A$5:$A$304,0))&"","No está en el inventario"))
B12: =IF($A12="","",IFERROR(INDEX('Inventario General'!$C$5:$C$304,MATCH($A12,'Inventario General'!$A$5:$A$304,0))&"","No está en el inventario")) | C12: =IF($A12="","",IFERROR(INDEX('Inventario General'!$D$5:$D$304,MATCH($A12,'Inventario General'!$A$5:$A$304,0))&"","No está en el inventario")) | D12: =IF($A12="","",IFERROR(INDEX('Inventario General'!$I$5:$I$304,MATCH($A12,'Inventario General'!$A$5:$A$304,0))&"","No está en el inventario"))
B13: =IF($A13="","",IFERROR(INDEX('Inventario General'!$C$5:$C$304,MATCH($A13,'Inventario General'!$A$5:$A$304,0))&"","No está en el inventario")) | C13: =IF($A13="","",IFERROR(INDEX('Inventario General'!$D$5:$D$304,MATCH($A13,'Inventario General'!$A$5:$A$304,0))&"","No está en el inventario")) | D13: =IF($A13="","",IFERROR(INDEX('Inventario General'!$I$5:$I$304,MATCH($A13,'Inventario General'!$A$5:$A$304,0))&"","No está en el inventario"))
B14: =IF($A14="","",IFERROR(INDEX('Inventario General'!$C$5:$C$304,MATCH($A14,'Inventario General'!$A$5:$A$304,0))&"","No está en el inventario")) | C14: =IF($A14="","",IFERROR(INDEX('Inventario General'!$D$5:$D$304,MATCH($A14,'Inventario General'!$A$5:$A$304,0))&"","No está en el inventario")) | D14: =IF($A14="","",IFERROR(INDEX('Inventario General'!$I$5:$I$304,MATCH($A14,'Inventario General'!$A$5:$A$304,0))&"","No está en el inventario"))
B15: =IF($A15="","",IFERROR(INDEX('Inventario General'!$C$5:$C$304,MATCH($A15,'Inventario General'!$A$5:$A$304,0))&"","No está en el inventario")) | C15: =IF($A15="","",IFERROR(INDEX('Inventario General'!$D$5:$D$304,MATCH($A15,'Inventario General'!$A$5:$A$304,0))&"","No está en el inventario")) | D15: =IF($A15="","",IFERROR(INDEX('Inventario General'!$I$5:$I$304,MATCH($A15,'Inventario General'!$A$5:$A$304,0))&"","No está en el inventario"))
B16: =IF($A16="","",IFERROR(INDEX('Inventario General'!$C$5:$C$304,MATCH($A16,'Inventario General'!$A$5:$A$304,0))&"","No está en el inventario")) | C16: =IF($A16="","",IFERROR(INDEX('Inventario General'!$D$5:$D$304,MATCH($A16,'Inventario General'!$A$5:$A$304,0))&"","No está en el inventario")) | D16: =IF($A16="","",IFERROR(INDEX('Inventario General'!$I$5:$I$304,MATCH($A16,'Inventario General'!$A$5:$A$304,0))&"","No está en el inventario"))
B17: =IF($A17="","",IFERROR(INDEX('Inventario General'!$C$5:$C$304,MATCH($A17,'Inventario General'!$A$5:$A$304,0))&"","No está en el inventario")) | C17: =IF($A17="","",IFERROR(INDEX('Inventario General'!$D$5:$D$304,MATCH($A17,'Inventario General'!$A$5:$A$304,0))&"","No está en el inventario")) | D17: =IF($A17="","",IFERROR(INDEX('Inventario General'!$I$5:$I$304,MATCH($A17,'Inventario General'!$A$5:$A$304,0))&"","No está en el inventario"))
... B204: =IF($A204="","",IFERROR(INDEX('Inventario General'!$C$5:$C$304,MATCH($A204,'Inventario General'!$A$5:$A$304,0))&"","No está en el inventario")) | C204: =IF($A204="","",IFERROR(INDEX('Inventario General'!$D$5:$D$304,MATCH($A204,'Inventario General'!$A$5:$A$304,0))&"","No está en el inventario")) | D204: =IF($A204="","",IFERROR(INDEX('Inventario General'!$I$5:$I$304,MATCH($A204,'Inventario General'!$A$5:$A$304,0))&"","No está en el inventario"))

Sheet Red y Comunicaciones
A1: FICHA TÉCNICA – RED Y COMUNICACIONES
A2: Switches, routers, firewalls, access points y demás equipos de red.
A4: Código patrimonial | B4: Marca | C4: Modelo | D4: Responsable | E4: Tipo de equipo de red | F4: N° de puertos | G4: Velocidad de puertos | H4: PoE | I4: Administrable | J4: Versión de firmware | K4: IP de gestión | L4: Dirección MAC | M4: VLAN configuradas | N4: Estándares / Protocolos | O4: Proveedor de internet (ISP) | P4: Ancho de banda contratado (Mbps) | Q4: Ubicación (rack / sala) | R4: Último respaldo de configuración | S4: Observaciones
A5: PAT-0003 | B5: =IF($A5="","",IFERROR(INDEX('Inventario General'!$C$5:$C$304,MATCH($A5,'Inventario General'!$A$5:$A$304,0))&"","No está en el inventario")) -> Cisco | C5: =IF($A5="","",IFERROR(INDEX('Inventario General'!$D$5:$D$304,MATCH($A5,'Inventario General'!$A$5:$A$304,0))&"","No está en el inventario")) -> Catalyst 9200L-24P | D5: =IF($A5="","",IFERROR(INDEX('Inventario General'!$I$5:$I$304,MATCH($A5,'Inventario General'!$A$5:$A$304,0))&"","No está en el inventario")) -> Equipo de TI | E5: Switch | F5: 24 | G5: 1 Gbps | H5: Sí | I5: Sí | J5: 17.9.4 | K5: 192.168.10.2 | L5: 00:1B:54:AA:BB:CC | M5: 10, 20, 30 | N5: 802.1Q, 802.3at (PoE+) | O5: ISP de ejemplo | P5: 300 | Q5: Sala de servidores - Rack 1 | R5: 46280 | S5: FILA DE EJEMPLO
B6: =IF($A6="","",IFERROR(INDEX('Inventario General'!$C$5:$C$304,MATCH($A6,'Inventario General'!$A$5:$A$304,0))&"","No está en el inventario")) | C6: =IF($A6="","",IFERROR(INDEX('Inventario General'!$D$5:$D$304,MATCH($A6,'Inventario General'!$A$5:$A$304,0))&"","No está en el inventario")) | D6: =IF($A6="","",IFERROR(INDEX('Inventario General'!$I$5:$I$304,MATCH($A6,'Inventario General'!$A$5:$A$304,0))&"","No está en el inventario"))
B7: =IF($A7="","",IFERROR(INDEX('Inventario General'!$C$5:$C$304,MATCH($A7,'Inventario General'!$A$5:$A$304,0))&"","No está en el inventario")) | C7: =IF($A7="","",IFERROR(INDEX('Inventario General'!$D$5:$D$304,MATCH($A7,'Inventario General'!$A$5:$A$304,0))&"","No está en el inventario")) | D7: =IF($A7="","",IFERROR(INDEX('Inventario General'!$I$5:$I$304,MATCH($A7,'Inventario General'!$A$5:$A$304,0))&"","No está en el inventario"))
B8: =IF($A8="","",IFERROR(INDEX('Inventario General'!$C$5:$C$304,MATCH($A8,'Inventario General'!$A$5:$A$304,0))&"","No está en el inventario")) | C8: =IF($A8="","",IFERROR(INDEX('Inventario General'!$D$5:$D$304,MATCH($A8,'Inventario General'!$A$5:$A$304,0))&"","No está en el inventario")) | D8: =IF($A8="","",IFERROR(INDEX('Inventario General'!$I$5:$I$304,MATCH($A8,'Inventario General'!$A$5:$A$304,0))&"","No está en el inventario"))
B9: =IF($A9="","",IFERROR(INDEX('Inventario General'!$C$5:$C$304,MATCH($A9,'Inventario General'!$A$5:$A$304,0))&"","No está en el inventario")) | C9: =IF($A9="","",IFERROR(INDEX('Inventario General'!$D$5:$D$304,MATCH($A9,'Inventario General'!$A$5:$A$304,0))&"","No está en el inventario")) | D9: =IF($A9="","",IFERROR(INDEX('Inventario General'!$I$5:$I$304,MATCH($A9,'Inventario General'!$A$5:$A$304,0))&"","No está en el inventario"))
B10: =IF($A10="","",IFERROR(INDEX('Inventario General'!$C$5:$C$304,MATCH($A10,'Inventario General'!$A$5:$A$304,0))&"","No está en el inventario")) | C10: =IF($A10="","",IFERROR(INDEX('Inventario General'!$D$5:$D$304,MATCH($A10,'Inventario General'!$A$5:$A$304,0))&"","No está en el inventario")) | D10: =IF($A10="","",IFERROR(INDEX('Inventario General'!$I$5:$I$304,MATCH($A10,'Inventario General'!$A$5:$A$304,0))&"","No está en el inventario"))
B11: =IF($A11="","",IFERROR(INDEX('Inventario General'!$C$5:$C$304,MATCH($A11,'Inventario General'!$A$5:$A$304,0))&"","No está en el inventario")) | C11: =IF($A11="","",IFERROR(INDEX('Inventario General'!$D$5:$D$304,MATCH($A11,'Inventario General'!$A$5:$A$304,0))&"","No está en el inventario")) | D11: =IF($A11="","",IFERROR(INDEX('Inventario General'!$I$5:$I$304,MATCH($A11,'Inventario General'!$A$5:$A$304,0))&"","No está en el inventario"))
B12: =IF($A12="","",IFERROR(INDEX('Inventario General'!$C$5:$C$304,MATCH($A12,'Inventario General'!$A$5:$A$304,0))&"","No está en el inventario")) | C12: =IF($A12="","",IFERROR(INDEX('Inventario General'!$D$5:$D$304,MATCH($A12,'Inventario General'!$A$5:$A$304,0))&"","No está en el inventario")) | D12: =IF($A12="","",IFERROR(INDEX('Inventario General'!$I$5:$I$304,MATCH($A12,'Inventario General'!$A$5:$A$304,0))&"","No está en el inventario"))
B13: =IF($A13="","",IFERROR(INDEX('Inventario General'!$C$5:$C$304,MATCH($A13,'Inventario General'!$A$5:$A$304,0))&"","No está en el inventario")) | C13: =IF($A13="","",IFERROR(INDEX('Inventario General'!$D$5:$D$304,MATCH($A13,'Inventario General'!$A$5:$A$304,0))&"","No está en el inventario")) | D13: =IF($A13="","",IFERROR(INDEX('Inventario General'!$I$5:$I$304,MATCH($A13,'Inventario General'!$A$5:$A$304,0))&"","No está en el inventario"))
B14: =IF($A14="","",IFERROR(INDEX('Inventario General'!$C$5:$C$304,MATCH($A14,'Inventario General'!$A$5:$A$304,0))&"","No está en el inventario")) | C14: =IF($A14="","",IFERROR(INDEX('Inventario General'!$D$5:$D$304,MATCH($A14,'Inventario General'!$A$5:$A$304,0))&"","No está en el inventario")) | D14: =IF($A14="","",IFERROR(INDEX('Inventario General'!$I$5:$I$304,MATCH($A14,'Inventario General'!$A$5:$A$304,0))&"","No está en el inventario"))
B15: =IF($A15="","",IFERROR(INDEX('Inventario General'!$C$5:$C$304,MATCH($A15,'Inventario General'!$A$5:$A$304,0))&"","No está en el inventario")) | C15: =IF($A15="","",IFERROR(INDEX('Inventario General'!$D$5:$D$304,MATCH($A15,'Inventario General'!$A$5:$A$304,0))&"","No está en el inventario")) | D15: =IF($A15="","",IFERROR(INDEX('Inventario General'!$I$5:$I$304,MATCH($A15,'Inventario General'!$A$5:$A$304,0))&"","No está en el inventario"))
B16: =IF($A16="","",IFERROR(INDEX('Inventario General'!$C$5:$C$304,MATCH($A16,'Inventario General'!$A$5:$A$304,0))&"","No está en el inventario")) | C16: =IF($A16="","",IFERROR(INDEX('Inventario General'!$D$5:$D$304,MATCH($A16,'Inventario General'!$A$5:$A$304,0))&"","No está en el inventario")) | D16: =IF($A16="","",IFERROR(INDEX('Inventario General'!$I$5:$I$304,MATCH($A16,'Inventario General'!$A$5:$A$304,0))&"","No está en el inventario"))
B17: =IF($A17="","",IFERROR(INDEX('Inventario General'!$C$5:$C$304,MATCH($A17,'Inventario General'!$A$5:$A$304,0))&"","No está en el inventario")) | C17: =IF($A17="","",IFERROR(INDEX('Inventario General'!$D$5:$D$304,MATCH($A17,'Inventario General'!$A$5:$A$304,0))&"","No está en el inventario")) | D17: =IF($A17="","",IFERROR(INDEX('Inventario General'!$I$5:$I$304,MATCH($A17,'Inventario General'!$A$5:$A$304,0))&"","No está en el inventario"))
... B204: =IF($A204="","",IFERROR(INDEX('Inventario General'!$C$5:$C$304,MATCH($A204,'Inventario General'!$A$5:$A$304,0))&"","No está en el inventario")) | C204: =IF($A204="","",IFERROR(INDEX('Inventario General'!$D$5:$D$304,MATCH($A204,'Inventario General'!$A$5:$A$304,0))&"","No está en el inventario")) | D204: =IF($A204="","",IFERROR(INDEX('Inventario General'!$I$5:$I$304,MATCH($A204,'Inventario General'!$A$5:$A$304,0))&"","No está en el inventario"))

Sheet Periféricos
A1: FICHA TÉCNICA – PERIFÉRICOS Y OTROS DISPOSITIVOS
A2: Impresoras, escáneres, monitores, proyectores, UPS, teléfonos IP, cámaras, etc.
A4: Código patrimonial | B4: Marca | C4: Modelo | D4: Responsable | E4: Tipo de periférico | F4: Conexión | G4: Resolución / Capacidad | H4: Dirección IP (si es de red) | I4: Consumibles (modelo) | J4: Contador de páginas / horas de uso | K4: Equipo asociado (código) | L4: Observaciones
A5: PAT-0004 | B5: =IF($A5="","",IFERROR(INDEX('Inventario General'!$C$5:$C$304,MATCH($A5,'Inventario General'!$A$5:$A$304,0))&"","No está en el inventario")) -> HP | C5: =IF($A5="","",IFERROR(INDEX('Inventario General'!$D$5:$D$304,MATCH($A5,'Inventario General'!$A$5:$A$304,0))&"","No está en el inventario")) -> LaserJet Pro MFP M428fdw | D5: =IF($A5="","",IFERROR(INDEX('Inventario General'!$I$5:$I$304,MATCH($A5,'Inventario General'!$A$5:$A$304,0))&"","No está en el inventario")) -> Área de Administración | E5: Multifuncional | F5: Ethernet y USB | G5: 1200 x 1200 dpi / 40 ppm | H5: 192.168.10.60 | I5: Tóner CF258A | J5: 18450 | L5: FILA DE EJEMPLO
B6: =IF($A6="","",IFERROR(INDEX('Inventario General'!$C$5:$C$304,MATCH($A6,'Inventario General'!$A$5:$A$304,0))&"","No está en el inventario")) | C6: =IF($A6="","",IFERROR(INDEX('Inventario General'!$D$5:$D$304,MATCH($A6,'Inventario General'!$A$5:$A$304,0))&"","No está en el inventario")) | D6: =IF($A6="","",IFERROR(INDEX('Inventario General'!$I$5:$I$304,MATCH($A6,'Inventario General'!$A$5:$A$304,0))&"","No está en el inventario"))
B7: =IF($A7="","",IFERROR(INDEX('Inventario General'!$C$5:$C$304,MATCH($A7,'Inventario General'!$A$5:$A$304,0))&"","No está en el inventario")) | C7: =IF($A7="","",IFERROR(INDEX('Inventario General'!$D$5:$D$304,MATCH($A7,'Inventario General'!$A$5:$A$304,0))&"","No está en el inventario")) | D7: =IF($A7="","",IFERROR(INDEX('Inventario General'!$I$5:$I$304,MATCH($A7,'Inventario General'!$A$5:$A$304,0))&"","No está en el inventario"))
B8: =IF($A8="","",IFERROR(INDEX('Inventario General'!$C$5:$C$304,MATCH($A8,'Inventario General'!$A$5:$A$304,0))&"","No está en el inventario")) | C8: =IF($A8="","",IFERROR(INDEX('Inventario General'!$D$5:$D$304,MATCH($A8,'Inventario General'!$A$5:$A$304,0))&"","No está en el inventario")) | D8: =IF($A8="","",IFERROR(INDEX('Inventario General'!$I$5:$I$304,MATCH($A8,'Inventario General'!$A$5:$A$304,0))&"","No está en el inventario"))
B9: =IF($A9="","",IFERROR(INDEX('Inventario General'!$C$5:$C$304,MATCH($A9,'Inventario General'!$A$5:$A$304,0))&"","No está en el inventario")) | C9: =IF($A9="","",IFERROR(INDEX('Inventario General'!$D$5:$D$304,MATCH($A9,'Inventario General'!$A$5:$A$304,0))&"","No está en el inventario")) | D9: =IF($A9="","",IFERROR(INDEX('Inventario General'!$I$5:$I$304,MATCH($A9,'Inventario General'!$A$5:$A$304,0))&"","No está en el inventario"))
B10: =IF($A10="","",IFERROR(INDEX('Inventario General'!$C$5:$C$304,MATCH($A10,'Inventario General'!$A$5:$A$304,0))&"","No está en el inventario")) | C10: =IF($A10="","",IFERROR(INDEX('Inventario General'!$D$5:$D$304,MATCH($A10,'Inventario General'!$A$5:$A$304,0))&"","No está en el inventario")) | D10: =IF($A10="","",IFERROR(INDEX('Inventario General'!$I$5:$I$304,MATCH($A10,'Inventario General'!$A$5:$A$304,0))&"","No está en el inventario"))
B11: =IF($A11="","",IFERROR(INDEX('Inventario General'!$C$5:$C$304,MATCH($A11,'Inventario General'!$A$5:$A$304,0))&"","No está en el inventario")) | C11: =IF($A11="","",IFERROR(INDEX('Inventario General'!$D$5:$D$304,MATCH($A11,'Inventario General'!$A$5:$A$304,0))&"","No está en el inventario")) | D11: =IF($A11="","",IFERROR(INDEX('Inventario General'!$I$5:$I$304,MATCH($A11,'Inventario General'!$A$5:$A$304,0))&"","No está en el inventario"))
B12: =IF($A12="","",IFERROR(INDEX('Inventario General'!$C$5:$C$304,MATCH($A12,'Inventario General'!$A$5:$A$304,0))&"","No está en el inventario")) | C12: =IF($A12="","",IFERROR(INDEX('Inventario General'!$D$5:$D$304,MATCH($A12,'Inventario General'!$A$5:$A$304,0))&"","No está en el inventario")) | D12: =IF($A12="","",IFERROR(INDEX('Inventario General'!$I$5:$I$304,MATCH($A12,'Inventario General'!$A$5:$A$304,0))&"","No está en el inventario"))
B13: =IF($A13="","",IFERROR(INDEX('Inventario General'!$C$5:$C$304,MATCH($A13,'Inventario General'!$A$5:$A$304,0))&"","No está en el inventario")) | C13: =IF($A13="","",IFERROR(INDEX('Inventario General'!$D$5:$D$304,MATCH($A13,'Inventario General'!$A$5:$A$304,0))&"","No está en el inventario")) | D13: =IF($A13="","",IFERROR(INDEX('Inventario General'!$I$5:$I$304,MATCH($A13,'Inventario General'!$A$5:$A$304,0))&"","No está en el inventario"))
B14: =IF($A14="","",IFERROR(INDEX('Inventario General'!$C$5:$C$304,MATCH($A14,'Inventario General'!$A$5:$A$304,0))&"","No está en el inventario")) | C14: =IF($A14="","",IFERROR(INDEX('Inventario General'!$D$5:$D$304,MATCH($A14,'Inventario General'!$A$5:$A$304,0))&"","No está en el inventario")) | D14: =IF($A14="","",IFERROR(INDEX('Inventario General'!$I$5:$I$304,MATCH($A14,'Inventario General'!$A$5:$A$304,0))&"","No está en el inventario"))
B15: =IF($A15="","",IFERROR(INDEX('Inventario General'!$C$5:$C$304,MATCH($A15,'Inventario General'!$A$5:$A$304,0))&"","No está en el inventario")) | C15: =IF($A15="","",IFERROR(INDEX('Inventario General'!$D$5:$D$304,MATCH($A15,'Inventario General'!$A$5:$A$304,0))&"","No está en el inventario")) | D15: =IF($A15="","",IFERROR(INDEX('Inventario General'!$I$5:$I$304,MATCH($A15,'Inventario General'!$A$5:$A$304,0))&"","No está en el inventario"))
B16: =IF($A16="","",IFERROR(INDEX('Inventario General'!$C$5:$C$304,MATCH($A16,'Inventario General'!$A$5:$A$304,0))&"","No está en el inventario")) | C16: =IF($A16="","",IFERROR(INDEX('Inventario General'!$D$5:$D$304,MATCH($A16,'Inventario General'!$A$5:$A$304,0))&"","No está en el inventario")) | D16: =IF($A16="","",IFERROR(INDEX('Inventario General'!$I$5:$I$304,MATCH($A16,'Inventario General'!$A$5:$A$304,0))&"","No está en el inventario"))
B17: =IF($A17="","",IFERROR(INDEX('Inventario General'!$C$5:$C$304,MATCH($A17,'Inventario General'!$A$5:$A$304,0))&"","No está en el inventario")) | C17: =IF($A17="","",IFERROR(INDEX('Inventario General'!$D$5:$D$304,MATCH($A17,'Inventario General'!$A$5:$A$304,0))&"","No está en el inventario")) | D17: =IF($A17="","",IFERROR(INDEX('Inventario General'!$I$5:$I$304,MATCH($A17,'Inventario General'!$A$5:$A$304,0))&"","No está en el inventario"))
... B204: =IF($A204="","",IFERROR(INDEX('Inventario General'!$C$5:$C$304,MATCH($A204,'Inventario General'!$A$5:$A$304,0))&"","No está en el inventario")) | C204: =IF($A204="","",IFERROR(INDEX('Inventario General'!$D$5:$D$304,MATCH($A204,'Inventario General'!$A$5:$A$304,0))&"","No está en el inventario")) | D204: =IF($A204="","",IFERROR(INDEX('Inventario General'!$I$5:$I$304,MATCH($A204,'Inventario General'!$A$5:$A$304,0))&"","No está en el inventario"))

Sheet Software y Licencias
A1: REGISTRO DE SOFTWARE Y LICENCIAS
A2: No guarde claves sensibles aquí si el archivo se comparte; use el número de contrato o una referencia al gestor de contraseñas.
A4: ID de licencia | B4: Software | C4: Versión | D4: Fabricante | E4: Tipo de licencia | F4: Cantidad adquirida | G4: Cantidad en uso | H4: Disponibles | I4: Clave / N° de contrato | J4: Fecha de adquisición | K4: Fecha de vencimiento | L4: Estado de la licencia | M4: Costo (S/) | N4: Proveedor | O4: Instalada en (código o descripción) | P4: Responsable de la licencia | Q4: Observaciones
A5: LIC-0001 | B5: Microsoft 365 Business Standard | C5: 2024 | D5: Microsoft | E5: Suscripción anual | F5: 25 | G5: 22 | H5: =IF(F5="","",F5-G5) -> 3 | I5: Contrato MS-2025-118 | J5: 45962 | K5: 46326 | L5: =IF(E5="","",IF(E5="Perpetua","Perpetua",IF(K5="","Sin fecha",IF(K5<TODAY(),"Vencida",IF(K5-TODAY()<=Listas!$T$2,"Por vencer","Vigente"))))) -> Por vencer | M5: 15000 | N5: Proveedor Tecnológico S.A.C. | O5: Equipos de usuario | P5: Equipo de TI | Q5: FILA DE EJEMPLO
H6: =IF(F6="","",F6-G6) | L6: =IF(E6="","",IF(E6="Perpetua","Perpetua",IF(K6="","Sin fecha",IF(K6<TODAY(),"Vencida",IF(K6-TODAY()<=Listas!$T$2,"Por vencer","Vigente")))))
H7: =IF(F7="","",F7-G7) | L7: =IF(E7="","",IF(E7="Perpetua","Perpetua",IF(K7="","Sin fecha",IF(K7<TODAY(),"Vencida",IF(K7-TODAY()<=Listas!$T$2,"Por vencer","Vigente")))))
H8: =IF(F8="","",F8-G8) | L8: =IF(E8="","",IF(E8="Perpetua","Perpetua",IF(K8="","Sin fecha",IF(K8<TODAY(),"Vencida",IF(K8-TODAY()<=Listas!$T$2,"Por vencer","Vigente")))))
